Workbook

Sheet README
A1: Supplementary material: Trusted Execution for Sensor-Based Health Diagnostics: A Scoping Review and Attestation Appraisal Profile
A2: Reporting guideline: PRISMA-ScR. Searches run in OpenAlex on 2026-10-12 (see 'Search log').
A3: Sheets: Coding rules (element definitions and counting rules); Search log (queries and counts); Criteria (inclusion and exclusion codes, incl. the 2026-10-12 amendment); Screening (all 435 records with decisions); Included studies (charting of the 55 included studies); PRISMA counts (formulas over 'Screening').
A4: MITC elements: D device identity, F firmware/code, A acquisition configuration, C calibration, M model version, N freshness, H(R) reading digest. 1 = the study protects the element as stated in the source; blank = not stated.
A5: Charting source: 'Full text' or 'Abstract only'. Abstract-only coding is provisional and conservative (an element is coded only if the abstract states it).
A6: Screening decisions were suggested by keyword rules and an AI assistant (Claude, Anthropic) and checked by the author.
A7: Evidence levels: studies read in full form the primary synthesis (Tables II-III and the gap findings); abstract-only studies are supplementary evidence with provisional coding ('Evidence level' column).
A8: Screening sheet, Next-to-last column: retrieval outcome for each of the 72 reports sought (full text obtained, or not retrieved and assessed on title and abstract). Included studies sheet: 'Evidence type for coded elements' distinguishes implemented and evaluated protection, design-only proposals, formal-only verification, and demonstrated weaknesses (attacks).

Sheet Coding rules
A1: Element | B1: Coded when the study (read in full for primary studies)... | C1: Not coded when... | D1: Example
A2: D: device identity | B2: binds data or keys to a specific physical device: PUF responses, device keys certified by a manufacturer/PKI, or physical fingerprints used to identify the device | C2: a key exists but is not tied to a device identity (e.g., shared symmetric key) | D2: Gas-sensor PUFs; Yoshida (PUF root of trust); Shams (TEE-generated key + X.509 certificate)
A3: F: firmware or code | B3: a verifier checks measurements of the code that processes readings (remote attestation, measured boot with quote) | C3: secure boot only, with no evidence available to a remote verifier | D3: PAtt (hash of PLC logic); ImageBox (attested SGX classifier); Benlloch-Lopez (TPM quote, design only)
A4: A: acquisition configuration | B4: actual sensor or peripheral configuration registers (not just driver code) are read and checked by a verifier | C4: only firmware containing a driver is attested | D4: ERAMO: BME280 ctrl_hum/ctrl_meas/config and I2C registers checked at attestation time (not per reading; ADC not covered)
A5: C: calibration | B5: calibration parameters, version, or update authorization are protected or bound to results | C5: calibration is only named as a threat | D5: None; Li et al. names calibration deviation as a threat only
A6: M: model version | B6: the model used is bound to the result (identity), or model updates are authorized/versioned | C6: the model is only kept confidential | D6: ImageBox (model identity recorded, no version policy); Benlloch-Lopez (signed, version-controlled updates, design only); SecureQNN excluded (confidentiality only)
A7: N: freshness | B7: each reading or attestation includes a nonce, counter, or timestamp checked by the verifier | C7: timestamps exist but are not protected or checked | D7: PAtt (verifier nonce); Cabrera-Gutierrez (HSM/TEE timestamp); Hu (nonces, formal verification only)
A8: H(R): reading digest | B8: each reading (or batch) is signed, MACed, or hashed so the verifier can detect alteration | C8: data are only encrypted in transit without per-reading integrity at the source | D8: Yoshida, Oyama (PUF-keyed MAC per frame); Shams (TEE-signed readings); Heiss (signed measurements verified in enclave)
A9: Counting rule | B9: A single mechanism can count for two elements only when both conditions are separately met (e.g., a certified device key counts as D; the per-reading signature made with it counts as H(R)).
A10: Evidence types | B10: Implemented and evaluated; Design only (no evaluation); Formal verification only; Weakness shown (attack, not protection); Per abstract (supplementary, provisional). Recorded in the Included studies sheet.
A11: Evidence levels | B11: Primary: charted from full text (used for Table II and the gap findings). Supplementary: charted from abstract only; an element is coded only if the abstract states it, so absence is not evidence of absence.

Sheet Search log
A1: Search ID | B1: Database | C1: Exact query | D1: Date run (YYYY-MM-DD) | E1: Results shown
A2: R1 | B2: OpenAlex (completed) | C2: title-abstract-keywords has (stemmed "confidential computing" AND stemmed "medical IoT") | D2: 2026-10-12 | E2: 1
A3: R2 | B3: OpenAlex (completed) | C3: title-abstract-keywords has (stemmed "breath analysis" AND privacy) | D3: 2026-10-12 | E3: 16
A4: R3 | B4: OpenAlex (completed) | C4: title-abstract-keywords has (authentication AND stemmed "gas sensor") | D4: 2026-10-12 | E4: 71
A5: R4 | B5: OpenAlex (completed) | C5: title-abstract-keywords has (stemmed "electronic nose" AND security) | D5: 2026-10-12 | E5: 182
A6: R5 | B6: OpenAlex (completed) | C6: title-abstract-keywords has (provenance AND stemmed "trusted sensor") | D6: 2026-10-12 | E6: 1
A7: R6 | B7: OpenAlex (completed) | C7: title-abstract-keywords has (stemmed "remote attestation" AND sensor) | D7: 2026-10-12 | E7: 54
A8: R7 | B8: OpenAlex (completed) | C8: title-abstract-keywords has (stemmed "trusted execution environment" AND "sensor") | D8: 2026-10-12 | E8: 84
A9: R8 | B9: OpenAlex (completed) | C9: title-abstract-keywords has ((stemmed "trusted execution environment" OR TrustZone OR SGX OR enclave OR stemmed "remote attestation" OR stemmed "confidential computing" OR stemmed "physically unclonable function") AND (stemmed "electronic nose" OR stemmed "gas sensor" OR stemmed "chemical sensor" OR stemmed "breath analysis" OR "exhaled breath" OR chemiresistive)) | D9: 2026-10-12 | E9: 20

Sheet Criteria
A1: Code | B1: Rule
A2: I1 | B2: Proposes or evaluates a TEE, attestation, PUF/device-identity, or cryptographic mechanism that protects the integrity, authenticity, or confidentiality of sensor or health DATA: the readings, their processing, or results derived from them (including authenticating the origin of readings). Protecting only an ML model does not qualify (clarified 2026-10-17). Narrowed on 2026-10-12, before full-text review.
A3: I2 | B3: Or: applies ML or data handling to chemical-sensor arrays (e-nose, gas, breath) AND addresses security, privacy, integrity, or authentication.
A4: I3 | B4: Peer-reviewed paper or widely cited preprint, published 2012–2026, with an English title and abstract (as applied at screening; one included full text in Chinese was read in translation).
A5: E1 | B5: Off topic: not about the security or trust of sensing or health data (e.g., biology "enclave", sensor chemistry with no security aspect).
A6: E2 | B6: No technical design or evaluation (editorial, news, opinion, abstract only).
A7: E3 | B7: Not in English.
A8: E4 | B8: Duplicate or earlier version of an included paper.
A9: E5 | B9: Full text not available.
A10: E6 | B10: Published outside 2012–2026.
A11: E7 | B11: Not peer-reviewed (thesis, podcast, dataset or code repository, webinar, self-published report).
A12: E8 | B12: Protects device, firmware, or platform state only, not sensor or health DATA (narrower rule of 2026-10-12, applied retrospectively to every record that had passed title/abstract screening). Scope clarified 2026-10-17 to include ML-model-only protection (one further exclusion, S0383). May still be cited as background.
A13: Note | B13: Title/abstract stage: decide Include, Exclude (with code), or Maybe. Maybe goes to full-text review. Full-text stage: Include, or Exclude with code.

Sheet Screening
A1: Record ID | B1: Source | C1: Search ID | D1: Title | E1: Authors | F1: Year | G1: Venue | H1: DOI / ID | I1: Duplicate of (Record ID) | J1: T/A decision | K1: T/A reason | L1: Full-text decision | M1: FT reason | N1: Mechanism | O1: Pipeline stage | P1: Asset protected | Q1: Chemical-sensor data? (Y/N) | R1: Notes | S1: Retrieval outcome (eligibility stage)
A2: R0001 | B2: Other: web check | C2: — | D2: Trusted Operations on Sensor Data | E2: H. Janjua, W. Joosen, S. Michiels, D. Hughes | F2: 2018 | G2: Sensors 18(5), 1364 | H2: 10.3390/s18051364 | J2: Include | L2: Include | N2: TrustZone (OP-TEE) secure operations on sensor data | O2: Acquisition | P2: Secrecy, integrity, freshness of readings | Q2: N | R2: Full text read. Raspberry Pi 3 + BLE pulse sensor; timing overhead only; no calibration or drift. | Pulse sensor and camera on Raspberry Pi 3; no gas sensors; evaluation reports timing, not drift or calibration. | S2: Full text obtained and read
A3: R0002 | B3: Other: web check | C3: — | D3: Gas Sensor Physically Unclonable Function-Based Lightweight Bidirectional Authentication Protocol for Gas Sensor Networks | E3: S. Hu, P. Wang, H. He, Y. Zhang, X. Li | F3: 2024 | G3: Electronics 13(17), 3385 | H3: 10.3390/electronics13173385 | I3: S0026 | J3: Exclude | K3: E4 | N3: Gas-sensor PUF + auth protocol | O3: Device identity | P3: Node authentication | Q3: Y | R3: ZnO-SnO2 sensor array as PUF; >98% reliability over 20 days; not breath, no TEE.
A4: R0003 | B4: Other: web check | C4: — | D4: High Steady-state Physical Unclonable Function Generator Based on Gas Sensors | E4: P. Wang, L. Li, Y. Zheng, G. Li | F4: 2021 | G4: J. Electronics & Information Technology 43(6), 1596–1602 | H4: 10.11999/JEIT201104 | J4: Include | L4: Include | N4: Gas-sensor PUF (Pd-SnO2 nanofibers; 8-sensor array, 3-sensor cluster comparisons, 128-bit response) | O4: Device identity | P4: Node identity | Q4: Y | R4: Full text read (Chinese full text; English title and abstract; JEIT 43(6):1596-1602, 2021). Formaldehyde stimulus; reliability 97.85% tested only across heater voltage 4.2-4.9 V (5 samples) and a 400 s run at room conditions (100% for 90 s, >95% after); humidity and long-term drift not tested. Uniqueness 49.04%; randomness 97.03% in abstract vs 98.06% in text. No authentication protocol, reading or calibration binding. Elements: D. | Pd-SnO2 sensors, formaldehyde; check whether full text is English (E3 if not). | S4: Full text obtained and read
A5: R0004 | B5: Other: web check | C5: — | D5: Fingerprinting Analog IoT Sensors for Secret-Free Authentication | E5: F. Lorenz et al. | F5: 2020 | G5: arXiv preprint | H5: arXiv:2006.06296 | J5: Maybe | L5: Exclude | M5: E7 | N5: Analog sensor fingerprinting (temperature sensors) | O5: Transduction | P5: Sensor authenticity | Q5: N | R5: Full text read. arXiv preprint only. Cite as background for analog trust boundary. | Temperature sensors; relevant to the analog trust boundary. | S5: Full text obtained and read
A6: R0005 | B6: Other: web check | C6: — | D6: This Ain't Your Dose: Sensor Spoofing Attack on Medical Infusion Pump | E6: Y. Park, Y. Son, H. Shin, D. Kim, Y. Kim | F6: 2016 | G6: USENIX WOOT 2016 | H6: woot16-paper-park | J6: Include | L6: Include | N6: Sensor spoofing attack on infusion-pump drop sensor | O6: Transduction | P6: Medical sensor integrity | Q6: N | R6: Full text read. Laser spoofing from ~12 m; over-infusion up to ~3.3x. Physical attack below any TEE. | Physical spoofing of a medical sensor; supports the transduction threat in Table I. | S6: Full text obtained and read
A7: R0006 | B7: Other: web check | C7: — | D7: PDRIMA: A Policy-Driven Runtime Integrity Measurement and Attestation Approach for ARM TrustZone-based TEE | E7: J. Mao, X. Chang | F7: 2025 | G7: arXiv preprint | H7: arXiv:2512.06500 | J7: Exclude | K7: E8 | N7: TrustZone runtime attestation | O7: Device / runtime | P7: TEE runtime integrity | Q7: N | R7: General TrustZone attestation; no sensors. Likely E1 at full text unless used as background.
A8: S0001 | B8: OpenAlex | C8: R1 | D8: Protecting patient confidentiality in the Internet of Medical Things through confidential computing | E8: Richard Searle, Prabhanjan Gururaj | F8: 2023 | H8: https://doi.org/10.69554/ccmf2668 | J8: Include | L8: Exclude | M8: E2 | N8: Conceptual confidential-computing architecture | O8: Analytics | P8: PHI confidentiality | Q8: N | R8: Charted from abstract only. Position paper; no implementation or evaluation. Cite as background. | Confidential computing for IoMT data | S8: Full text not retrieved (paywalled or unavailable); assessed on title and abstract
A9: S0002 | B9: OpenAlex | C9: R2 | D9: Breath analysis using FTIR spectroscopy | E9: Andrei A. Bunaciu, Hassan Youssef Aboul-Enein | F9: 2025 | H9: https://doi.org/10.37349/emed.2025.1001308 | J9: Exclude | K9: E1 | R9: Off topic: sensing or security application without protection of sensor/health data
A10: S0003 | B10: OpenAlex | C10: R2 | D10: The AI Nose Knows: Digital Olfaction and Emotional Scent | E10: Rocky Scopelliti | F10: 2026 | H10: https://doi.org/10.1201/9781003737063-12 | J10: Exclude | K10: E1 | R10: Off topic: sensing or security application without protection of sensor/health data
A11: S0004 | B11: OpenAlex | C11: R2 | D11: The digitization of health care retailing | E11: Mark Scott Rosenbaum, Germán Contreras Ramírez, Karen Edwards, Ji-Yeon Kim, J Campbell, Marianne C. Bickle | F11: 2017 | H11: https://doi.org/10.1108/jrim-07-2017-0058 | J11: Exclude | K11: E1 | R11: Off topic: sensing or security application without protection of sensor/health data
A12: S0005 | B12: OpenAlex | C12: R2 | D12: Artificial Intelligence for Noninvasive Health Diagnostics | E12: Pushkar Wankhede, Devendra Bhuyar, Shrinivas R. Zanwar, Rohit Pawar, Mahendra R. Jadhav, Nisarg Gandhewar, Madhusudan B. Kulkarni, Manish L. Bhaiyya, Hossam Haick | F12: 2025 | H12: https://doi.org/10.1021/acssensors.5c03171 | J12: Exclude | K12: E1 | R12: Off topic: sensing or security application without protection of sensor/health data
A13: S0006 | B13: OpenAlex | C13: R2 | D13: AI-Integrated biosensors: A paradigm shift in multi-cancer detection with enhanced sensitivity and specificity | E13: Fatima Naseer, Ufra Naseer, Muhammad Yousaf, Junnan Wei, Yuxuan Gao, Dan Li, Xiujia Tian, Yanqing Liu, Xueyan Li, Fang Wang, Ping Luo | F13: 2026 | H13: https://doi.org/10.1016/j.snr.2026.100439 | J13: Exclude | K13: E1 | R13: Off topic: sensing or security application without protection of sensor/health data
A14: S0007 | B14: OpenAlex | C14: R2 | D14: Breath as a biomarker: A survey of contact and contactless applications and approaches in respiratory monitoring | E14: A.L.M.U.S.T.A.P.H.A.A. WAKILI, Babajide J. Asaju, Woosub Jung | F14: 2025 | H14: https://doi.org/10.1016/j.smhl.2025.100579 | J14: Exclude | K14: E1 | R14: Off topic: sensing or security application without protection of sensor/health data
A15: S0008 | B15: OpenAlex | C15: R2 | D15: A Review and Performance Study of AI Techniques in Asthma Prediction | E15: Dr Prashant Kumar Srivastava | F15: 2026 | J15: Exclude | K15: E1 | R15: Off topic: sensing or security application without protection of sensor/health data
A16: S0009 | B16: OpenAlex | C16: R2 | D16: Synthetic Exhaled Breath Data-Based Edge AI Model for the Prediction of Chronic Obstructive Pulmonary Disease | E16: Samson Otieno Ooko, Didacienne Mukanyiligira, Jean Pierre Munyampundu, Jimmy Nsenga | F16: 2021 | H16: https://doi.org/10.1109/i3cat53310.2021.9629420 | J16: Exclude | K16: E1 | R16: Off topic: sensing or security application without protection of sensor/health data
A17: S0010 | B17: OpenAlex | C17: R2 | D17: Impaction-based exhaled breath sampling for substance monitoring: a prospective pilot study (Drugxhale) | E17: Lutea A. A. de Jong, Erik J. H. Olyslager, Jan A Wieferink, Maarten Keizer, Tobias Cornielje, Robbert Peter Zuidema | F17: 2024 | H17: https://doi.org/10.1088/1752-7163/ad80b6 | J17: Exclude | K17: E1 | R17: Off topic: sensing or security application without protection of sensor/health data
A18: S0011 | B18: OpenAlex | C18: R2 | D18: Capture and analysis of amphetamine-like stimulants in exhaled breath using functionalized cotton fibers | E18: Zirun Ren, Litao Shao, Yudi Zhang, Bin Di, Mengxiang Su | F18: 2026 | H18: https://doi.org/10.1016/j.microc.2026.119098 | J18: Exclude | K18: E1 | R18: Off topic: sensing or security application without protection of sensor/health data
A19: S0012 | B19: OpenAlex | C19: R2 | D19: Disposable Face Masks for Noninvasive Drug Detection: A Proof-of-Concept Study with Cough Syrup Constituents | E19: Hei-Tak Tse, Jian Zhen Yu, Zongwei Cai, Wan Chan | F19: 2025 | H19: https://doi.org/10.1021/acs.analchem.5c01129 | J19: Exclude | K19: E1 | R19: Off topic: sensing or security application without protection of sensor/health data
A20: S0013 | B20: OpenAlex | C20: R2 | D20: Capture and Analysis of Amphetamine-like Stimulants in Exhaled Breath Using Functionalized Cotton Fibers | E20: Zirun Ren, Litao Shao, Yudi Zhang, Bin Di, Mengxiang Su | F20: 2026 | H20: https://doi.org/10.2139/ssrn.6869062 | I20: S0011 | J20: Exclude | K20: E4 | R20: AI-suggested, confirm. Duplicate
A21: S0014 | B21: OpenAlex | C21: R2 | D21: Tiny Machine Learning (TinyML) Based Self Diagnostic Kit for Respiratory Diseases | E21: Samson Otieno Ooko, Jimmy Nsenga | F21: 2023 | H21: https://doi.org/10.1109/icca59364.2023.10401673 | J21: Exclude | K21: E1 | R21: Off topic: sensing or security application without protection of sensor/health data
A22: S0015 | B22: OpenAlex | C22: R2 | D22: State-of-the-art TinyML approaches for colorectal cancer detection: Current advances, challenges, and future directions | E22: Showkat Ahmad Bhat, Ming-Che Chen, Nen-Fu Huang | F22: 2026 | H22: https://doi.org/10.1016/j.artmed.2026.103481 | J22: Exclude | K22: E1 | R22: Off topic: sensing or security application without protection of sensor/health data
A23: S0016 | B23: OpenAlex | C23: R2 | D23: Public Preferences for Emerging Cancer Screening Modalities: A Systematic Review of Discrete Choice Experiments | E23: Chee Ern Har, Qi Gao, Wenjia Chen, Yi Wang | F23: 2025 | H23: https://doi.org/10.1007/s40271-025-00775-1 | J23: Exclude | K23: E1 | R23: Off topic: sensing or security application without protection of sensor/health data
A24: S0017 | B24: OpenAlex | C24: R2 | D24: ONCO-VOC AI module | E24: Ioannis Gallos | F24: 2026 | H24: https://doi.org/10.5281/zenodo.19203817 | J24: Exclude | K24: E7 | R24: AI-suggested, confirm. Not peer-reviewed (thesis, podcast, dataset, repository, webinar)
A25: S0018 | B25: OpenAlex | C25: R3 | D25: Detection of Authentication of Milk by Nanostructure Conducting Polypyrrole-ZnO | E25: Sajad Pirsa, Şeref Tağı, Mohammad Rezaei | F25: 2021 | H25: https://doi.org/10.1007/s11664-021-08855-2 | J25: Exclude | K25: E1 | R25: Off topic: sensing or security application without protection of sensor/health data
A26: S0019 | B26: OpenAlex | C26: R3 | D26: Housing Society Management, Authentication and Security App | E26: Durga Bhavani.A | F26: 2017 | H26: https://doi.org/10.18535/ijecs/v6i6.05 | J26: Exclude | K26: E1 | R26: Off topic: sensing or security application without protection of sensor/health data
A27: S0020 | B27: OpenAlex | C27: R3 | D27: Human Body Odor Based Authentication Using Machine Learning | E27: Yang Bin, Wonjun Lee | F27: 2018 | H27: https://doi.org/10.1109/ssci.2018.8628697 | J27: Maybe | L27: Include | N27: Gas-sensor odor biometric + ML (K-means, PCA, NN) | O27: Inference | P27: Person identity (I2) | Q27: Y | R27: Full text read (IEEE SSCI 2018). Body-odor samples from MQ-series gas sensors; K-means, PCA and neural network identify individuals with high accuracy. Shows odor data are identifying (I2). No protection mechanism. No elements coded. | Odor biometric | S27: Full text obtained and read
A28: S0021 | B28: OpenAlex | C28: R3 | D28: Design and Implementation of Industrial security system using Fingerprint Authentication and IOT | E28: Ch. Narasimha Rao, M. Rambabu | F28: 2018 | J28: Exclude | K28: E1 | R28: Off topic: sensing or security application without protection of sensor/health data
A29: S0022 | B29: OpenAlex | C29: R3 | D29: CBC (Cipher Block Chaining)-Based Authenticated Encryption for Securing Sensor Data in Smart Home | E29: S Rajashree, Rajkumar Sukumar | F29: 2021 | H29: https://doi.org/10.1007/978-3-030-71485-7_12 | J29: Include | L29: Include | N29: AES-128-CBC encryption with CBC-MAC for sensor data before transmission | O29: Transmission | P29: Confidentiality and integrity of sensor data in transit | Q29: N | R29: Full text read (Springer/EAI chapter, 2021). ESP32 with DHT11 temperature-humidity sensor; timestamped readings written to a file and encrypted with AES-CBC, last block used as MAC. Gas sensors mentioned only as a possible addition, so no chemical-sensor data were used (reclassified from Y). No performance evaluation, device-side protection, freshness, attestation, calibration or model binding. No elements coded. | Authenticated encryption of smart-home sensor data | S29: Full text obtained and read
A30: S0023 | B30: OpenAlex | C30: R3 | D30: Automated Detection of Porcine Gelatin Using Deep Learning-Based E-Nose to Support Halal Authentication | E30: Kunti Robiatul Mahmudah, Muhammad Kunta Biddinika, Dhias Cahya Hakika, Wildan Panji Tresna, Iyon Titok Sugiarto, Inna Syafarina | F30: 2025 | H30: https://doi.org/10.35882/jeeemi.v7i1.654 | J30: Exclude | K30: E1 | R30: Off topic: sensing or security application without protection of sensor/health data
A31: S0024 | B31: OpenAlex | C31: R3 | D31: Odor-based individual authentication | E31: Wataru Tanaka, Chaiyanut Jirayupat, Haruka Honda, Jiangyang Liu, Takuro Hosomi, Tsunaki Takahashi, Takeshi Yanagida | F31: 2025 | H31: https://doi.org/10.1039/d5cc02465j | J31: Maybe | L31: Exclude | M31: E2 | N31: Review of odor-based authentication (skin, breath) | O31: — | P31: — | Q31: Y | R31: Charted from abstract only. Review without own evaluation; cite as background for breath re-identification risk. | Odor biometric | S31: Full text not retrieved (paywalled or unavailable); assessed on title and abstract
A32: S0025 | B32: OpenAlex | C32: R3 | D32: Authentication and adulteration detection of true cinnamon (Cinnamomum zeylanicum) essential oil using an integrated multi-analytical and electronic nose approach | E32: Giovana Feltes, Ilizandra Aparecida Fernandes, Juliana Steffens, Natália Paroul, Clarice Steffens | F32: 2026 | H32: https://doi.org/10.1016/j.compag.2026.111825 | J32: Exclude | K32: E1 | R32: Off topic: sensing or security application without protection of sensor/health data
A33: S0026 | B33: OpenAlex | C33: R3 | D33: Gas Sensor Physically Unclonable Function-Based Lightweight Bidirectional Authentication Protocol for Gas Sensor Networks | E33: Shuang Hu, Pengjun Wang, Haonan He, Yuejun Zhang, Xiangyu Li | F33: 2024 | H33: https://doi.org/10.3390/electronics13173385 | J33: Include | L33: Include | N33: Gas-sensor PUF (ZnO-SnO2 array) + lightweight bidirectional user-server-node authentication protocol (hash, XOR, nonces), ProVerif-verified | O33: Device identity / transmission | P33: Node authentication; session key for transmitting gas data | Q33: Y | R33: Full text read (Electronics 2024, 13(17), 3385). D: GS-PUF response hashed for node authentication; ethanol and methanol stimuli. N: user and server random numbers per session; formally resists replay, impersonation, node tampering and cloning (ProVerif only, no hardware protocol timing). Gas data sent under a session key (confidentiality), but individual readings are not digested or signed. No calibration, firmware or model binding. Elements: D, N. | Gas-sensor PUF authentication protocol | S33: Full text obtained and read
A34: S0027 | B34: OpenAlex | C34: R3 | D34: Identification authentication scheme using human body odour | E34: Minglei Shu, Yunxiang Liu, Hua Fang | F34: 2014 | H34: https://doi.org/10.1109/ccsse.2014.7224531 | J34: Maybe | L34: Exclude | M34: E2 | N34: Odor identification scheme (gas sensor arrays) | O34: — | P34: — | Q34: Y | R34: Charted from abstract only. Theoretical analysis only, no experiments. | Odor biometric | S34: Full text not retrieved (paywalled or unavailable); assessed on title and abstract
A35: S0028 | B35: OpenAlex | C35: R3 | D35: Data processing approaches and strategies for non-destructive fruits quality inspection and authentication: a review | E35: Satyam Srivastava, Shashikant Sadistap | F35: 2018 | H35: https://doi.org/10.1007/s11694-018-9893-2 | J35: Exclude | K35: E1 | R35: Off topic: sensing or security application without protection of sensor/health data
A36: S0029 | B36: OpenAlex | C36: R3 | D36: Design of Gas Sensors-Based PUF for Internet of Things Security | E36: Xiaowei Zhang, Zexin Ji, Xiangyu Li, Pengjun Wang, Yangong Zheng, Shanshan Wang | F36: 2025 | H36: https://doi.org/10.1109/jsen.2025.3540015 | J36: Include | L36: Include | N36: Gas-sensor PUF (TiO2-ZnO nanofibers; 128-bit) | O36: Device identity | P36: Node identity and key management | Q36: Y | R36: Full text read (IEEE Sensors J. 25(7), 2025). Eight TiO2-ZnO sensors, three per cluster, median averaging filter + multi-bit balancing, 128-bit response; varied gas concentrations and operating voltages; uniqueness 49.6%, randomness 98.6%, reliability 97%. Authentication and key management claimed as applications only, no protocol. Humidity not tested. Elements: D. | Gas-sensor PUF (IEEE Sensors J. 2025) | S36: Full text obtained and read
A37: S0030 | B37: OpenAlex | C37: R3 | D37: NASICON-based gas sensor utilizing MMnO3 (M: Gd, Sm, La) sensing electrode for triethylamine detection | E37: Yueying Zhang, Ce Ma, Xinyu Yang, Yang Song, Xishuang Liang, Xu Zhao, Yilin Wang, Yuan Lou Gao, Fengmin Liu, Fangmeng Liu, Peng Sun, Geyu Lu | F37: 2019 | H37: https://doi.org/10.1016/j.snb.2019.05.062 | J37: Exclude | K37: E1 | R37: Off topic: sensing or security application without protection of sensor/health data
A38: S0031 | B38: OpenAlex | C38: R3 | D38: Metal Oxide Semiconductor Gas Sensors-based E-nose and Two-stage Classification: Authentication of Malaysia and Vietnam Black Pepper Samples | E38: Hui En Lee, Zehnder Jarroop Augustine Mercer, Sing Muk Ng, Mahnaz Shafiei, Hong Siang Chua | F38: 2022 | H38: https://doi.org/10.1109/isoen54820.2022.9789618 | J38: Exclude | K38: E1 | R38: Off topic: sensing or security application without protection of sensor/health data
A39: S0032 | B39: OpenAlex | C39: R3 | D39: Potential application of electronic nose coupled with chemometric tools for authentication assessment in tomato paste | E39: Ayat Mohammad‐Razdari, Mahdi Ghasemi‐Varnamkhasti, Seyedeh Hoda Yoosefian, Zahra Izadi, Maryam Siadat | F39: 2019 | H39: https://doi.org/10.1111/jfpe.13119 | J39: Exclude | K39: E1 | R39: Off topic: sensing or security application without protection of sensor/health data
A40: S0033 | B40: OpenAlex | C40: R3 | D40: Rapid analysis of meat floss origin using a supervised machine learning-based electronic nose towards food authentication | E40: Linda Ardita Putri, Iman Rahman, Mayumi Puspita, Shidiq Nur Hidayat, Agus Budi Dharmawan, Aditya Rianjanu, Sunu Wibirama, Roto Roto, Kuwat Trıyana, Hutomo Suryo Wasisto | F40: 2023 | H40: https://doi.org/10.1038/s41538-023-00205-2 | J40: Exclude | K40: E1 | R40: Off topic: sensing or security application without protection of sensor/health data
...

Sheet Included studies
A1: Record ID | B1: Ref. no. in paper | C1: Authors | D1: Year | E1: Title | F1: Venue | G1: DOI / ID | H1: Mechanism | I1: Pipeline stage | J1: Asset protected | K1: Chemical-sensor data (Y/N) | L1: D | M1: F | N1: A | O1: C | P1: M | Q1: N | R1: H(R) | S1: Elements (count) | T1: Charting source | U1: Evidence type for coded elements | V1: Notes | W1: Evidence level | X1: Mechanism category
A2: R0001 | B2: 19 | C2: H. Janjua, W. Joosen, S. Michiels, D. Hughes | D2: 2018 | E2: Trusted Operations on Sensor Data | F2: Sensors 18(5), 1364 | G2: 10.3390/s18051364 | H2: TrustZone (OP-TEE) secure operations on sensor data | I2: Acquisition | J2: Secrecy, integrity, freshness of readings | K2: N | R2: 1 | S2: =SUM(L2:R2) -> 1 | T2: Full text | U2: Implemented and evaluated | V2: Full text read. Raspberry Pi 3 + BLE pulse sensor; timing overhead only; no calibration or drift. | Pulse sensor and camera on Raspberry Pi 3; no gas sensors; evaluation reports timing, not drift or calibration. | W2: Primary synthesis | X2: TEE or enclave
A3: R0003 | B3: 23 | C3: P. Wang, L. Li, Y. Zheng, G. Li | D3: 2021 | E3: High Steady-state Physical Unclonable Function Generator Based on Gas Sensors | F3: J. Electronics & Information Technology 43(6), 1596–1602 | G3: 10.11999/JEIT201104 | H3: Gas-sensor PUF (Pd-SnO2 nanofibers; 8-sensor array, 3-sensor cluster comparisons, 128-bit response) | I3: Device identity | J3: Node identity | K3: Y | L3: 1 | S3: =SUM(L3:R3) -> 1 | T3: Full text | U3: Implemented (Chinese full text read) | V3: Full text read (Chinese full text; English title and abstract; JEIT 43(6):1596-1602, 2021). Formaldehyde stimulus; reliability 97.85% tested only across heater voltage 4.2-4.9 V (5 samples) and a 400 s run at room conditions (100% for 90 s, >95% after); humidity and long-term drift not tested. Uniqueness 49.04%; randomness 97.03% in abstract vs 98.06% in text. No authentication protocol, reading or calibration binding. Elements: D. | Pd-SnO2 sensors, formaldehyde; check whether full text is English (E3 if not). | W3: Primary synthesis | X3: PUF only
A4: R0005 | B4: 17 | C4: Y. Park, Y. Son, H. Shin, D. Kim, Y. Kim | D4: 2016 | E4: This Ain't Your Dose: Sensor Spoofing Attack on Medical Infusion Pump | F4: USENIX WOOT 2016 | G4: woot16-paper-park | H4: Sensor spoofing attack on infusion-pump drop sensor | I4: Transduction | J4: Medical sensor integrity | K4: N | S4: =SUM(L4:R4) -> 0 | T4: Full text | U4: Weakness shown (attack) | V4: Full text read. Laser spoofing from ~12 m; over-infusion up to ~3.3x. Physical attack below any TEE. | Physical spoofing of a medical sensor; supports the transduction threat in Table I. | W4: Primary synthesis | X4: Other (isolation monitor, spoofing attack)
A5: S0020 | B5: 45 | C5: Yang Bin, Wonjun Lee | D5: 2018 | E5: Human Body Odor Based Authentication Using Machine Learning | G5: https://doi.org/10.1109/ssci.2018.8628697 | H5: Gas-sensor odor biometric + ML (K-means, PCA, NN) | I5: Inference | J5: Person identity (I2) | K5: Y | S5: =SUM(L5:R5) -> 0 | T5: Full text | V5: Full text read (IEEE SSCI 2018). Body-odor samples from MQ-series gas sensors; K-means, PCA and neural network identify individuals with high accuracy. Shows odor data are identifying (I2). No protection mechanism. No elements coded. | AI-suggested, confirm. Odor biometric | W5: Primary synthesis | X5: Breath or odor ML
A6: S0022 | B6: 41 | C6: S Rajashree, Rajkumar Sukumar | D6: 2021 | E6: CBC (Cipher Block Chaining)-Based Authenticated Encryption for Securing Sensor Data in Smart Home | G6: https://doi.org/10.1007/978-3-030-71485-7_12 | H6: AES-128-CBC encryption with CBC-MAC for sensor data before transmission | I6: Transmission | J6: Confidentiality and integrity of sensor data in transit | K6: N | S6: =SUM(L6:R6) -> 0 | T6: Full text | V6: Full text read (Springer/EAI chapter, 2021). ESP32 with DHT11 temperature-humidity sensor; timestamped readings written to a file and encrypted with AES-CBC, last block used as MAC. Gas sensors mentioned only as a possible addition, so no chemical-sensor data were used (reclassified from Y). No performance evaluation, device-side protection, freshness, attestation, calibration or model binding. No elements coded. | AI-suggested, confirm. Authenticated encryption of smart-home sensor data | W6: Primary synthesis | X6: Cryptography only
A7: S0026 | B7: 22 | C7: Shuang Hu, Pengjun Wang, Haonan He, Yuejun Zhang, Xiangyu Li | D7: 2024 | E7: Gas Sensor Physically Unclonable Function-Based Lightweight Bidirectional Authentication Protocol for Gas Sensor Networks | G7: https://doi.org/10.3390/electronics13173385 | H7: Gas-sensor PUF (ZnO-SnO2 array) + lightweight bidirectional user-server-node authentication protocol (hash, XOR, nonces), ProVerif-verified | I7: Device identity / transmission | J7: Node authentication; session key for transmitting gas data | K7: Y | L7: 1 | Q7: 1 | S7: =SUM(L7:R7) -> 2 | T7: Full text | U7: D implemented; N formal verification only (ProVerif) | V7: Full text read (Electronics 2024, 13(17), 3385). D: GS-PUF response hashed for node authentication; ethanol and methanol stimuli. N: user and server random numbers per session; formally resists replay, impersonation, node tampering and cloning (ProVerif only, no hardware protocol timing). Gas data sent under a session key (confidentiality), but individual readings are not digested or signed. No calibration, firmware or model binding. Elements: D, N. | AI-suggested, confirm. Gas-sensor PUF authentication protocol | W7: Primary synthesis | X7: PUF only
A8: S0029 | B8: 25 | C8: Xiaowei Zhang, Zexin Ji, Xiangyu Li, Pengjun Wang, Yangong Zheng, Shanshan Wang | D8: 2025 | E8: Design of Gas Sensors-Based PUF for Internet of Things Security | G8: https://doi.org/10.1109/jsen.2025.3540015 | H8: Gas-sensor PUF (TiO2-ZnO nanofibers; 128-bit) | I8: Device identity | J8: Node identity and key management | K8: Y | L8: 1 | S8: =SUM(L8:R8) -> 1 | T8: Full text | U8: Implemented and evaluated | V8: Full text read (IEEE Sensors J. 25(7), 2025). Eight TiO2-ZnO sensors, three per cluster, median averaging filter + multi-bit balancing, 128-bit response; varied gas concentrations and operating voltages; uniqueness 49.6%, randomness 98.6%, reliability 97%. Authentication and key management claimed as applications only, no protocol. Humidity not tested. Elements: D. | AI-suggested, confirm. Gas-sensor PUF (IEEE Sensors J. 2025) | W8: Primary synthesis | X8: PUF only
A9: S0042 | C9: Jaswanth Kumar N, N H Shrinandh, Jayasree M. Oli, Paramasivam C. | D9: 2026 | E9: A Secured Distributed IoT Framework for Real-Time Wildfire Detection using Edge Computing and Spatial-Temporal Correlation | G9: https://doi.org/10.1109/icoei68323.2026.11541877 | H9: ECDSA P-256 message authentication + multi-node consensus (ESP32, MQ gas sensors) | I9: Transmission | J9: Authenticity/integrity of gas readings | K9: Y | S9: =SUM(L9:R9) -> 0 | T9: Abstract only | V9: Charted from abstract only (abstract supplied by author). Wildfire detection; signing at a Python gateway; consensus of 2+ nodes within 500 m. No TEE. | AI-suggested, confirm. Secured sensor framework | W9: Supplementary (abstract only) | X9: Cryptography only
A10: S0046 | C10: V. T. Vithya, M. P. Chandrasekar, M. Suganthy, J. Jasmine Hephzipah, B. Sarala, Nuthakki Praveena, M. Perarasi | D10: 2022 | E10: Crptography based Lifi for Patient Privacy and Emergency Health Service Using IOT | G10: https://doi.org/10.17762/ijritcc.v10i2s.5928 | H10: SHA hashing for LiFi health IoT data | I10: Transmission | J10: Patient vital-sign data | K10: Y | S10: =SUM(L10:R10) -> 0 | T10: Abstract only | V10: Charted from abstract only. Vital-sign kit includes a gas sensor (not breath). Low technical depth. | AI-suggested, confirm. Crypto for health IoT; low technical depth? | W10: Supplementary (abstract only) | X10: Cryptography only
A11: S0051 | B11: 27 | C11: Haitao Mei, Yuejun Zhang, Haonan He, Yangong Zheng | D11: 2023 | E11: Design of High-Performance Gas-Sensing PUF Based on Nanoparticles/Fibers With Composite Morphology | G11: https://doi.org/10.1109/jsen.2023.3312323 | H11: Gas-sensor PUF (EHD nano-SnO2 particle/fiber) + PUF-based gas discrimination scheme | I11: Device identity | J11: Sensor identity; gas discrimination from per-gas PUF difference | K11: Y | L11: 1 | S11: =SUM(L11:R11) -> 1 | T11: Full text | U11: Implemented and evaluated | V11: Full text read (IEEE Sensors J. 23(20), 2023). EHD nano-SnO2 particle/fiber sensors; ethanol and formaldehyde at different temperatures; reliability 99.21%, uniqueness 49.37%, NIST pass. Gas authentication scheme distinguishes two reducing gases by PUF-response difference (min HD 57.1% between gases vs max 3.9% across 4.5-4.7 V): a selectivity aid, not authentication of samples or readings. Humidity not tested. Elements: D. | AI-suggested, confirm. Gas-sensing PUF (IEEE Sensors J. 2023) | W11: Primary synthesis | X11: PUF only
A12: S0056 | B12: 30 | C12: Xiali Han, Shanshan Wang, Jianding Yu, Pengjun Wang, Xiangyu Li | D12: 2026 | E12: Design of PUF based on a Cr2O3-SnO2 gas sensor for Internet of Things security | G12: https://doi.org/10.1016/j.measurement.2026.121395 | H12: Gas-sensor PUF (Cr2O3-SnO2; block-mapped random projection; 128-bit) | I12: Device identity | J12: Node identity and key management | K12: Y | L12: 1 | S12: =SUM(L12:R12) -> 1 | T12: Abstract only | U12: Implemented (per abstract, not verified) | V12: Charted from abstract only (full text unavailable). Uniqueness 50.02%, randomness 98.83%, reliability 97.21%; ML modeling attacks near 0.5 accuracy for 8 models; resistant to environmental disturbance (per abstract). No data binding, TEE, or health use stated. | AI-suggested, confirm. Gas-sensor PUF (Measurement 2026) | W12: Supplementary (abstract only) | X12: PUF only
A13: S0069 | B13: 42 | C13: Sanjay Patidar, Rajni Jindal, Neetesh Kumar | D13: 2024 | E13: A secure and energy-efficient edge computing improved SZ 2.1 hybrid algorithm for handling iot data stream | G13: https://doi.org/10.1007/s11042-024-18765-0 | H13: Error-bounded SZ 2.1 lossy compression + ChaCha20-Poly1305 authenticated encryption at the edge | I13: Transmission | J13: Confidentiality, integrity and authentication of IoT data streams in transit | K13: N | S13: =SUM(L13:R13) -> 0 | T13: Full text | V13: Full text read (Multimed. Tools Appl., 2024). Raspberry Pi client; datasets: driver stress (ECG, HR, GSR, RR) and UCI gas sensors for home activity monitoring, but only the temperature readings of the gas dataset were used, so no chemical-sensor data (reclassified from Y). Per-message Poly1305 MAC with 128-bit nonce; reports energy and processing-time reductions. No device-side protection, attestation, calibration or model binding. No elements coded. | AI-suggested, confirm. Secure IoT data stream | W13: Primary synthesis | X13: Cryptography only
A14: S0206 | B14: 44 | C14: Anna Paleczek, Justyna Grochala, Dominik Grochala, Agnieszka Pręgowska, Magdalena E Osial, Richard O. Oyeleke, Małgorzata Pihut, Jolanta E. Loster, Artur Maciej Rydosz | D14: 2025 | E14: The exhaled breath pattern as a potential method for biometrics identification | G14: https://doi.org/10.1038/s41598-025-19463-z | H14: Portable e-nose + ML (11 MOX/electrochemical sensors) | I14: Inference | J14: Breath profile (attribute inference) (I2) | K14: Y | S14: =SUM(L14:R14) -> 0 | T14: Full text | V14: Full text read. 94 participants; gender predicted from breath at 87.5% accuracy, BMI MAE ~4 kg/m2. Shows breath data reveal personal attributes. Notes sensor drift and need for encryption. | AI-suggested, confirm. Breath as biometric -> re-identification risk | W14: Primary synthesis | X14: Breath or odor ML
A15: S0250 | C15: Ashutosh Desai | D15: 2024 | E15: Person Identification using E-Nose : A quantitative study on identifying individuals based on exhale patterns | H15: IMS e-nose breath identification + 6 ML classifiers | I15: Inference | J15: Person identity from breath (I2) | K15: Y | S15: =SUM(L15:R15) -> 0 | T15: Abstract only | V15: Charted from abstract only. 30 participants, 3 sessions on different days. Ion mobility spectrometry, not chemiresistive. | AI-suggested, confirm. Exhaled-breath identification -> re-identification risk | W15: Supplementary (abstract only) | X15: Breath or odor ML
A16: S0280 | C16: Yusnani Mohd Yussoff, Nazhatul Hafizah Kamarudin, Habibah Hashim | D16: 2017 | E16: Lightweight Trusted Authentication Protocol for Wireless Sensor Network (WSN) | H16: Trusted (TCG-based) authentication protocol for WSN | I16: Device identity | J16: Node authenticity against clone/false messages | K16: N | S16: =SUM(L16:R16) -> 0 | T16: Abstract only | V16: Charted from abstract only. Suggests e-health use. | AI-suggested, confirm. Trusted auth for WSN, e-health use | W16: Supplementary (abstract only) | X16: Cryptography only
A17: S0287 | B17: 48 | C17: Edlira Dushku, Jeppe Hagelskjar Ostergaard, Nicola Dragoni | D17: 2022 | E17: Memory Offloading for Remote Attestation of Multi-Service IoT Devices | G17: https://doi.org/10.3390/s22124340 | H17: TrustZone-M attestation with memory offloading incl. peripheral registers (ERAMO) | I17: Acquisition | J17: Sensor-peripheral configuration integrity | K17: N | N17: 1 | S17: =SUM(L17:R17) -> 1 | T17: Full text | U17: Implemented and evaluated | V17: Full text read (Sensors 22(12), 4340, 2022; rechecked 2026-10-17). LPC55S69 (TrustZone-M), FreeRTOS. Attests all readable memory incl. memory-mapped peripheral registers; verifier checks I2C peripheral CFG/INTENSET/CLKDIV and BME280 configuration bits in ctrl_hum (0xF2), ctrl_meas (0xF4) and config (0xF5), i.e. acquisition settings (MITC field A). ADC configuration discussed as a risk but not verified; analog water-level sensor not attested; readings (dynamic registers) excluded. ~3.94 s combined attestation at 806,400 baud. | AI-suggested, confirm. ERAMO: attests peripheral memory on TrustZone MCU | W17: Primary synthesis | X17: TEE or enclave
A18: S0292 | B18: 31 | C18: Kota Yoshida, Kuniyasu Suzaki, Takeshi Fujino | D18: 2021 | E18: Towards Trusted IoT Sensing Systems: Implementing PUF as Secure Key Generator for Root of Trust and Message Authentication Code | G18: https://doi.org/10.1145/3505253.3505258 | H18: PUF-attested TEE (RISC-V Keystone) on main device + PUF-based MAC on subordinate sensor | I18: Acquisition / processing | J18: Reading authenticity from correct device + attested processing | K18: N | L18: 1 | M18: 1 | R18: 1 | S18: =SUM(L18:R18) -> 3 | T18: Full text | U18: Implemented and evaluated | V18: Full text read (HASP 2021 workshop, ACM). Main device: PRINCE glitch PUF as root of trust for RISC-V Keystone on FPGA; remote attestation of device key, security-monitor hash and enclave hash. Sensor: CMOS image-sensor PUF simulated on Raspberry Pi over Ethernet; per-image MAC (CMAC/HMAC) verified in enclave, ~18-19 ms per 640x480 image. Elements: D, F, H(R). Confidentiality out of scope; no freshness/replay protection for readings stated; no calibration or model binding. | AI-suggested, confirm. PUF root of trust + MAC for IoT sensing | W18: Primary synthesis | X18: TEE or enclave
A19: S0294 | B19: 36 | C19: Hamid Reza Ghaeini, Matthew Chan, Raad Bahmani, Ferdinand Brasser, Garcia, Luis, Jianying Zhou, Ahmad‐Reza Sadeghi, Nils Ole Tippenhauer, Saman Zonouz | D19: 2019 | E19: PAtt: Physics-based Attestation of Control Systems | G19: https://doi.org/10.60882/cispa.24612948 | H19: Physics-based software attestation without trusted hardware: nonce-seeded hash of PLC logic encoded as actuation, verified from resulting sensor traces | I19: Acquisition / control | J19: Integrity of PLC logic and authenticity of attestation sensor readings | K19: N | L19: 1 | M19: 1 | Q19: 1 | S19: =SUM(L19:R19) -> 3 | T19: Full text | U19: Implemented and evaluated | V19: Full text read (RAID 2019). Siemens S7-1200 PLC + robot arm testbed. F: hash over PLC logic code blocks. N: fresh verifier nonce in each attestation. D: verifier identifies each PLC and physical system by its process noise signature (PUF-like). Detects manipulated logic and replayed/spoofed sensor readings with 97% accuracy. Sensor readings serve as attestation evidence only; routine readings are not digested or signed (H(R) not coded). No calibration, model or acquisition-config binding. Elements: D, F, N. | AI-suggested, confirm. Binds attestation to physical sensor traces | W19: Primary synthesis | X19: Attestation without TEE
A20: S0297 | C20: Ivan De Oliveira Nunes, Xuhua Ding, Gene Tsudik | D20: 2021 | E20: On the Root of Trust Identification Problem | G20: https://doi.org/10.1145/3412382.3458274 | H20: Root-of-trust identification problem | I20: Device identity | J20: Which physical device produced a sensed value | K20: N | S20: =SUM(L20:R20) -> 0 | T20: Abstract only | V20: Charted from abstract only. Problem analysis for TEE-based sensing and actuation. | AI-suggested, confirm. Which device holds the RoT; sensing | W20: Supplementary (abstract only) | X20: Attestation without TEE
A21: S0298 | C21: Hong Zhong, Wenwen Cao, Qingyang Zhang, Jing Zhang, Jie Cui | D21: 2021 | E21: Toward Trusted and Secure Communication Among Multiple Internal Modules in CAV | G21: https://doi.org/10.1109/jiot.2021.3082542 | H21: Remote attestation + HMAC for in-vehicle module data (Intel SGX) | I21: Transmission | J21: Integrity of sensed data between modules | K21: N | S21: =SUM(L21:R21) -> 0 | T21: Abstract only | V21: Charted from abstract only (abstract supplied by author). Proven secure under CDH in the random oracle model. | AI-suggested, confirm. | W21: Supplementary (abstract only) | X21: TEE or enclave
A22: S0300 | C22: Mohamed A. El-Zawawy, Harsha Vasudev, Mauro Conti | D22: 2024 | E22: BDMFA: Forensic-enabling attestation technique for Internet of Medical Things | G22: https://doi.org/10.1016/j.iot.2024.101464 | H22: Blockchain + deep-learning medical attestation (SMART-based) | I22: Acquisition / analytics | J22: Medical sensor reading consistency; attestation history | K22: N | S22: =SUM(L22:R22) -> 0 | T22: Abstract only | V22: Charted from abstract only. Uses inconsistent medical sensor readings as compromise signal; 50 patient-sensors, 2.6 s attestation (simulation). | AI-suggested, confirm. IoMT attestation using medical sensor readings; SMART-based | W22: Supplementary (abstract only) | X22: Attestation without TEE
A23: S0313 | C23: I.O. Shevtsov, Tetiana Fesenko | D23: 2026 | E23: Developing a task allocation model for remote health monitoring in smart cities, considering latency, energy consumption, and privacy on fog nodes | G23: https://doi.org/10.15587/2706-5448.2026.358187 | H23: TEE + RATS attestation for fog offloading of patient monitoring | I23: Analytics | J23: Patient data confidentiality on fog nodes | K23: N | S23: =SUM(L23:R23) -> 0 | T23: Abstract only | V23: Charted from abstract only. Simulation (YAFS); ECG/audio tasks. | AI-suggested, confirm. TEE + RATS attestation on fog nodes for remote patient monitoring (simulation) | W23: Supplementary (abstract only) | X23: TEE or enclave
A24: S0317 | B24: 33 | C24: Yongzhi Wang | D24: 2026 | E24: TEE Protected Drone Inspection for Critical Infrastructure: Securing Edge Analytics and Trust at Scale | G24: https://doi.org/10.54941/ahfe1007075 | H24: Attested enclave (platform unnamed) with attestation-gated mission key, in-enclave autoencoder anomaly detection, enclave-signed results | I24: Processing / transmission | J24: Confidentiality and integrity of sensor-derived results | K24: N | M24: 1 | S24: =SUM(L24:R24) -> 1 | T24: Full text | U24: Design only (no evaluation) | V24: Full text read (AHFE/IHSI 2026, open access; read via web reader). UAV infrastructure inspection. Pre-flight remote attestation of enclave measurement (F); mission key provisioned after attestation; results encrypted and signed with enclave key bound to attested instance (result signing, not per-reading digest). Autoencoder in enclave flags anomalous frames (no architecture, threshold or accuracy given). No freshness/nonce, model version, calibration or device identity. Design with qualitative security analysis only; no implementation or quantitative evaluation. Elements: F. | AI-suggested, confirm. TEE edge analytics of sensor data | W24: Primary synthesis | X24: TEE or enclave
A25: S0318 | C25: Francesco Alesiani, Sebastian Gajek | D25: 2016 | E25: Remote Testimony: How to Trust an Autonomous Vehicle | G25: https://doi.org/10.1109/vtcspring.2016.7504447 | H25: Remote testimony from signing, tamper-resistant sensors (no trusted computing) | I25: Acquisition | J25: Reliability of vehicle sensor data to peers | K25: N | S25: =SUM(L25:R25) -> 0 | T25: Abstract only | V25: Charted from abstract only (abstract supplied by author). | AI-suggested, confirm. | W25: Supplementary (abstract only) | X25: Attestation without TEE
A26: S0320 | C26: Ivan De Oliveira Nunes, Karim Eldefrawy, Norrathep Rattanavipanon, Gene Tsudik | D26: 2019 | E26: A Verified Architecture for Proofs of Execution on Remote Devices under Full Software Compromise | G26: https://doi.org/10.48550/arxiv.1908.02444 | H26: Formally verified proofs of execution binding outputs to code (VAPE/APEX) | I26: Acquisition | J26: Authenticity of sensor data produced by expected code | K26: N | S26: =SUM(L26:R26) -> 0 | T26: Full text | V26: Full text read. arXiv version; MSP430/AVR; low overhead. Check published version (APEX, USENIX Security 2020) for citation. | AI-suggested, confirm. VAPE: authenticated sensing on low-end MCUs | W26: Primary synthesis | X26: Attestation without TEE
A27: S0324 | B27: 40 | C27: Sergio Benlloch-Lopez, Miquel Viel-Vazquez, Javier Naranjo-Alcazar, Jordi Grau-Haro, Pedro Zuccarello | D27: 2026 | E27: Threat Modeling for Enhancing Security of IoT Audio Classification Devices Under a Secure Protocols Framework | G27: https://doi.org/10.1007/978-3-032-24807-7_45 | H27: TPM 2.0 measured boot and remote attestation gating a one-time LUKS unlock key; mTLS 1.3 with post-quantum hybrid; signed, versioned ML model updates; tamper sensors (no TEE) | I27: Acquisition / inference / transmission | J27: Audio features, on-device models, data at rest | K27: N | M27: 1 | P27: 1 | S27: =SUM(L27:R27) -> 2 | T27: Full text | U27: Design only (evaluation planned) | V27: Full text read (arXiv:2509.14657v3, Nov 2025; published Springer 2026). Raspberry Pi 4 + TPM 2.0 prototype design. F: boot stages measured into TPM PCRs, quote verified by server. M: model updates signed and version-controlled; rollback here means redeploying an earlier trusted version, not anti-rollback protection. Feature hashes and E2E encryption protect data in transit (not coded as per-reading digest). No freshness, calibration or acquisition-config binding. Evaluation planned only, no results. Elements: F, M. | AI-suggested, confirm. Sensor ML device threat model | W27: Primary synthesis | X27: Attestation without TEE
A28: S0327 | B28: 35 | C28: Antonio J. Cabrera-Gutiérrez, Encarnación Castillo, Antonio Escobar-Molero, Juan Cruz-Cozar, Diego Pedro Morales, Luis Parrilla | D28: 2023 | E28: Secure Sensor Prototype Using Hardware Security Modules and Trusted Execution Environments in a Blockchain Application: Wine Logistic Use Case | G28: https://doi.org/10.3390/electronics12132987 | H28: TF-M TEE + HSM signing sensor readings with timestamp | I28: Acquisition | J28: Reading authenticity and freshness | K28: N | Q28: 1 | R28: 1 | S28: =SUM(L28:R28) -> 2 | T28: Full text | U28: Implemented and evaluated | V28: Full text read. PSoC64, DPS310 pressure sensor; 1.09x vs hardware-HSM baseline. No calibration handling. | AI-suggested, confirm. HSM + TEE secure sensor | W28: Primary synthesis | X28: TEE or enclave
A29: S0329 | C29: Yin Liu, Breno Dantas Cruz, Eli Tilevich | D29: 2023 | E29: Trusted and privacy-preserving sensor data onloading | G29: https://doi.org/10.1016/j.comcom.2023.04.027 | H29: TEE middleware (Open-TEE on Android) + adaptive differential privacy + Trust-Data theory for spurious-data removal in sensor-data onloading | I29: Analytics | J29: Sensor-data privacy; detection of spurious data | K29: N | S29: =SUM(L29:R29) -> 0 | T29: Full text | V29: Full text read (author manuscript, Computer Communications 2023). Extended version of S0328. Apps deposit sensor data (e.g., geolocation, blood pressure) in a TEE-protected middleware that answers noisy statistical queries. No signing, attestation, freshness, calibration or model binding. No elements coded. | AI-suggested, confirm. | W29: Primary synthesis | X29: TEE or enclave
A30: S0330 | C30: Saeed Mirzamohammadi, Ardalan Amiri Sani | D30: 2018 | E30: Viola: Trustworthy Sensor Notifications for Enhanced Privacy on Mobile Systems | G30: https://doi.org/10.1109/tmc.2018.2812706 | H30: Verified sensor/indicator invariants enforced in kernel/hypervisor (Viola) | I30: Acquisition | J30: Sensor-access privacy | K30: N | S30: =SUM(L30:R30) -> 0 | T30: Full text | V30: Full text read. Read via author dissertation chapter. Camera/mic; Nexus 5, ODROID. | AI-suggested, confirm. | W30: Primary synthesis | X30: Other (isolation monitor, spoofing attack)
A31: S0331 | C31: Hongcheng Xie, Yu Guo, Xiaohua Jia | D31: 2021 | E31: Privacy-Preserving Location-Based Data Queries in Fog-Enhanced Sensor Networks | G31: https://doi.org/10.1109/jiot.2021.3135303 | H31: Somewhat homomorphic encryption + Intel SGX for location-based sensor queries | I31: Analytics | J31: Confidentiality of queries, sensor locations, sensor data | K31: N | S31: =SUM(L31:R31) -> 0 | T31: Abstract only | V31: Charted from abstract only (abstract supplied by author). | AI-suggested, confirm. | W31: Supplementary (abstract only) | X31: TEE or enclave
A32: S0332 | C32: Xin Liu, Zhenbin Guo, Jun Ma, Yuchen Song | D32: 2021 | E32: A Secure Authentication Scheme for Wireless Sensor Networks Based on DAC and Intel SGX | G32: https://doi.org/10.1109/jiot.2021.3097996 | H32: Dynamic authentication credentials + SGX-protected master key in WSN gateway | I32: Device identity | J32: Access to WSN data; authentication-table protection | K32: N | S32: =SUM(L32:R32) -> 0 | T32: Abstract only | V32: Charted from abstract only (abstract supplied by author). BAN logic, AVISPA, NS3 simulation. | AI-suggested, confirm. SGX for WSN auth | W32: Supplementary (abstract only) | X32: TEE or enclave
A33: S0333 | C33: Anil Yadav, Nitin Rakesh, Sujata Pandey, Rajat Kumar Singh | D33: 2019 | E33: Optimising the DTLS handshake design for TEE enabled sensor nodes | G33: https://doi.org/10.1504/ijsn.2019.101416 | H33: TEE-based DTLS handshake for sensor nodes | I33: Transmission | J33: Session keys for sensor data | K33: N | S33: =SUM(L33:R33) -> 0 | T33: Abstract only | V33: Charted from abstract only (abstract supplied by author). Lower memory footprint, small handshake-time penalty. | AI-suggested, confirm. TEE sensor nodes | W33: Supplementary (abstract only) | X33: TEE or enclave
A34: S0337 | B34: 38 | C34: Jonathan Heiss, Anselm Busse, Stefan Tai | D34: 2021 | E34: Trustworthy Pre-processing of Sensor Data in Data On-Chaining Workflows for Blockchain-Based IoT Applications | G34: https://doi.org/10.1007/978-3-030-91431-8_9 | H34: Trustworthy pre-processing of signed sensor data off-chain with Intel SGX (remote attestation) or zkSNARKs (ZoKrates) before blockchain | I34: Processing | J34: End-to-end integrity of pre-processed sensor data | K34: N | L34: 1 | M34: 1 | R34: 1 | S34: =SUM(L34:R34) -> 3 | T34: Full text | U34: Implemented and evaluated | V34: Full text read (arXiv:2110.15869, author version of ICSOC 2021, LNCS 13121). Sensor nodes sign measurements with a sensor key pair; gateway verifies signatures inside the enclave or proof and proves correct transformation (filtering, aggregation). SGX enclave verified by remote attestation. Proof-of-concept on smart-meter data; enclave pre-processing orders of magnitude faster than zkSNARKs; on-chain verification cost in gas. Pre-processing is generic data reduction; calibration not mentioned. Elements: D, F, H(R). | AI-suggested, confirm. TEE pre-processing of sensor data (relevant to calibration stage) | W34: Primary synthesis | X34: TEE or enclave
A35: S0340 | C35: Anil Yadav, Sujata Pandey, Rajat Kumar Singh, Nitin Rakesh | D35: 2020 | E35: Design of Psk Based Trusted Dtls for Smart Sensor Nodes | G35: https://doi.org/10.2174/2666255813999200708135353 | H35: TEE-based PSK DTLS handshake for smart sensor nodes | I35: Transmission | J35: Session keys for sensor data | K35: N | S35: =SUM(L35:R35) -> 0 | T35: Abstract only | V35: Charted from abstract only (abstract supplied by author). Handshake penalty cut from ~3.5 to ~1.5 ms. Extends S0333 (different handshake mode). | AI-suggested, confirm. TEE sensor nodes | W35: Supplementary (abstract only) | X35: TEE or enclave
A36: S0344 | B36: 32 | C36: Tatsuya Oyama, Manami Hagizaki, Shunsuke Okura, Takeshi Fujino | D36: 2024 | E36: Implementation of an Image Tampering Detection System with a CMOS Image Sensor PUF and OP-TEE | G36: https://doi.org/10.3390/s24227121 | H36: CMOS image-sensor PUF key + HMAC per frame, verified in OP-TEE | I36: Acquisition / inference | J36: Reading authenticity before ML inference | K36: N | L36: 1 | R36: 1 | S36: =SUM(L36:R36) -> 2 | T36: Full text | U36: Implemented and evaluated | V36: Full text read. ZCU104; worst-case 4-bit error in 132,000 regenerations; MAC overhead ~0.017%/frame. Closest precedent to MITC sensor-reading binding; tested in one environment only. | AI-suggested, confirm. Sensor PUF + OP-TEE: closest analog to MITC sensor binding | W36: Primary synthesis | X36: TEE or enclave
A37: S0345 | C37: Gregor Haas, Micheal Chung, David Kohlbrenner | D37: 2025 | E37: Enabling Confidential I/O on RISC-V Without Hardware Modifications | G37: https://doi.org/10.1145/3733801.3764196 | H37: Confidential I/O on RISC-V via PMP: driver enclaves on a modified Keystone compartmentalize peripheral drivers (sensors, accelerators) | I37: Acquisition / processing | J37: Confidentiality and integrity of peripheral data against untrusted drivers and OS | K37: N | S37: =SUM(L37:R37) -> 0 | T37: Full text | V37: Full text read (ACM CPSIoTSec 2025 workshop). Polarfire Icicle FPGA testbench with an ML accelerator (VTA) and an end-to-end inference application; stock RISC-V, software only. Peripheral isolation; enclaves can produce attestation reports but no per-reading evidence, freshness, calibration or model binding. No calibration mentioned. No elements coded (isolation, not evidence binding). | AI-suggested, confirm. Confidential peripheral I/O | W37: Primary synthesis | X37: TEE or enclave
A38: S0346 | B38: 34 | C38: Shengtuo Hu, Qi Alfred Chen, Jiwon Joung, Can Carlak, Yiheng Feng, Zhuoqing Morley Mao, Henry X. Liu | D38: 2020 | E38: CVShield | G38: https://doi.org/10.1145/3375706.3380552 | H38: TrustZone (OP-TEE) secure peripheral access for GPS reading; planned relocation of processing, encapsulation and transmission code via program slicing (CVShield) | I38: Acquisition | J38: Integrity of GPS readings against a compromised normal world | K38: N | S38: =SUM(L38:R38) -> 0 | T38: Full text | V38: Full text read (ACM AutoSec 2020 workshop, 4 pages). i.MX6 Cortex-A9; CSU/TZASC restrict GPS UART to secure world; ~0.686 ms per 7.91-byte poll. Only sensor reading implemented; processing, packet encapsulation and transmission are future work. No signing, digest, freshness, attestation, calibration or model binding. Hardware attacks such as GPS spoofing out of scope. No elements coded (isolation, not evidence binding). | AI-suggested, confirm. | W38: Primary synthesis | X38: TEE or enclave
